import traceback
import sys
from discord.ext import commands
import discord


class CommandErrorHandler:
    def __init__(self, bot):
        self.bot = bot

    async def on_command_error(self, ctx, error):
        """The event triggered when an error is raised while invoking a command.
        ctx   : Context
        error : Exception"""

        if hasattr(ctx.command, 'on_error'):
            return

        ignored = (commands.CommandNotFound, commands.UserInputError)
        error = getattr(error, 'original', error)

        if isinstance(error, ignored):
            return

        elif isinstance(error, commands.DisabledCommand):
            return await ctx.send(f'{ctx.command} has been disabled. '
                                  'If you believe this was a mistake, please contact @Willy#7692')

        elif isinstance(error, commands.NoPrivateMessage):
            return await ctx.author.send(f'{ctx.command} can not be used in Private Messages.')

        elif isinstance(error, commands.BadArgument):
            if ctx.command.qualified_name == '':
                return await ctx.send('I could not find that member. Please try again.')

        print('Ignoring exception in command {}:'.format(ctx.command), file=sys.stderr)
        traceback.print_exception(type(error), error, error.__traceback__, file=sys.stderr)


def setup(bot):
    bot.add_cog(CommandErrorHandler(bot))
